Workbook

Sheet HTML Generator Dashboard
A1: Hia Solar Master Design v2.0 - LINE OA Drawing Content Portal Generator
A2: ระบบแปลงข้อมูลรายการแบบถอยประกอบจาก Excel ให้เป็น Code หน้าเว็บโมเดิร์นคลีน (Dark Theme)

Sheet Drawing List Database
A1: หมวดหมู่หลัก (Main Cat) | B1: Vendor | C1: Structure Type | D1: Structure Code | E1: Material Code | F1: Google Drive File URL
A2: E1 | B2: Huawei 2020 | C2: 1-Leg | D2: E1-G1L-HW.pdf | E2: 81301500168 | F2: =_xlfn.XLOOKUP(D2,Sheet1!C:C,Sheet1!E:E,0) -> 1yNq4z9_Zf-EVsKqtNbuQ5v4W9xOfnsT3
A3: E1 | B3: Hatari | C3: 1-Leg | D3: E1-G1L-C-Hatari-1-Slab.pdf | E3: 81301500160 | F3: =_xlfn.XLOOKUP(D3,Sheet1!C:C,Sheet1!E:E,0) -> 1UUDUiS7ANbUYhLk3me_8oDn6pMG2jfYT
A4: E1 | B4: Hatari | C4: 1-Leg | D4: E1-G1L-C-Hatari-1-Soil.pdf | E4: 81301500256 | F4: =_xlfn.XLOOKUP(D4,Sheet1!C:C,Sheet1!E:E,0) -> 1NbIq090KFG_wrYiD-U0-e4P5TCAQYE0U
A5: E1 | B5: Hatari | C5: 1-Leg | D5: E1-G1L-C-Hatari-2-Slab.pdf | E5: 81301500257 | F5: =_xlfn.XLOOKUP(D5,Sheet1!C:C,Sheet1!E:E,0) -> 1r8JLhcKS6rCZbfiUy66nXE8VJA6kX_F9
A6: E1 | B6: Hatari | C6: 1-Leg | D6: E1-G1L-C-Hatari-2-Soil.pdf | E6: 81301500258 | F6: =_xlfn.XLOOKUP(D6,Sheet1!C:C,Sheet1!E:E,0) -> 1kBKgOelz0qlK5AEENq8V6xkgVn17rgte
A7: E1 | B7: A-Plus | C7: 1-Leg | D7: E1-G1L-C-Aplus-Slab.pdf | E7: 81301500173 | F7: =_xlfn.XLOOKUP(D7,Sheet1!C:C,Sheet1!E:E,0) -> 1geEYmQI6fINaxQkXCKeWmB_3CZB2m8bW
A8: E1 | B8: Transpower | C8: 1-Leg | D8: E1-G1L-C-Transpower-H-Slab.pdf | E8: New request-2 | F8: =_xlfn.XLOOKUP(D8,Sheet1!C:C,Sheet1!E:E,0) -> 10In5XjyZlfD15fBecD3lrLwj9hkpWNXn
A9: E1 | B9: Transpower | C9: 1-Leg | D9: E1-G1L-C-Transpower-H-Soil.pdf | E9: New request-3 | F9: =_xlfn.XLOOKUP(D9,Sheet1!C:C,Sheet1!E:E,0) -> 11K1f04ZLijvHhHieef3OME7LgRV2a-rB
A10: E1 | B10: Transpower | C10: 1-Leg | D10: E1-G1L-C-Transpower-V-Slab.pdf | E10: New request-4 | F10: =_xlfn.XLOOKUP(D10,Sheet1!C:C,Sheet1!E:E,0) -> 100nbKdr6FIAClLOncY0C0aIM0h0AG2d9
A11: E1 | B11: Transpower | C11: 1-Leg | D11: E1-G1L-C-Transpower-V-Soil.pdf | E11: New request-5 | F11: =_xlfn.XLOOKUP(D11,Sheet1!C:C,Sheet1!E:E,0) -> 172DCyPSuXJYpT4Ws7FigO5ENDNIrmTPG
A12: E1 | B12: Huawei 2020 | C12: 2-Leg | D12: E1-G2L-HW.pdf | E12: 81301500166 | F12: =_xlfn.XLOOKUP(D12,Sheet1!C:C,Sheet1!E:E,0) -> 18XWF2f2vyKhemprwF-_oVq6AqoFMxsri
A13: E1 | B13: Qualia | C13: 2-Leg | D13: E1-G2L-C-Qualia.pdf | E13: 81301500167 | F13: =_xlfn.XLOOKUP(D13,Sheet1!C:C,Sheet1!E:E,0) -> 1mXHFwhsW8N4APfwTeo899MHBAw8xNHSR
A14: E1 | B14: Interlink | C14: 2-Leg | D14: E1-G2L-C-ITEL-Slab.pdf | E14: 81301500262 | F14: =_xlfn.XLOOKUP(D14,Sheet1!C:C,Sheet1!E:E,0) -> 1LP9R6KvNAS8nKTbS4KHMVgqnekpLUv-v
A15: E1 | B15: Interlink | C15: 2-Leg | D15: E1-G1L-MRV-3PV-4PV_Soil.pdf | E15: 81301500165 | F15: =_xlfn.XLOOKUP(D15,Sheet1!C:C,Sheet1!E:E,0) -> 136Dmht6m_OF3coDAYRVAB1xBq9ZWqRiO
A16: E1 | B16: A-Plus | C16: 2-Leg | D16: E1-G2L-C-Aplus-Soil.pdf | E16: 81301500171 | F16: =_xlfn.XLOOKUP(D16,Sheet1!C:C,Sheet1!E:E,0) -> 1LQSZp8WBfiz8GKZHyjP7E1BWAclDvbr1
A17: E1 | B17: A-Plus | C17: 1-Layer | D17: E1-T1-APlus.pdf | E17: 81301500239 | F17: =_xlfn.XLOOKUP(D17,Sheet1!C:C,Sheet1!E:E,0) -> 13drwIPa8sG3i1ILXjSrA0O_EVP67SN0l
A18: E1 | B18: A-Plus | C18: 2-Layer (4+2) | D18: E1-T2-Aplus.pdf | E18: 81301500244 | F18: =_xlfn.XLOOKUP(D18,Sheet1!C:C,Sheet1!E:E,0) -> 1tAi1YK8aU1n1DABUVJK1cOugzhNYQdf9
A19: E2 | B19: A-Plus | C19: 2-Leg | D19: E2-G2L-C-Aplus-Slab.pdf | E19: 81301500261 | F19: =_xlfn.XLOOKUP(D19,Sheet1!C:C,Sheet1!E:E,0) -> 1ULlDfXUrJykZV3D-Hcj0CExSMgAW1FoH
A20: E2 | B20: Qualia | C20: 2-Leg | D20: E2-G2L-C-Qualia-Slab.pdf | E20: 81301500260 | F20: =_xlfn.XLOOKUP(D20,Sheet1!C:C,Sheet1!E:E,0) -> 1QZKVeZP4k0ea250yEbvx2tdnWi_KFcyP
A21: E2 | B21: Qualia | C21: 2-Leg | D21: E2-G2L-C-Qualia-Soil.pdf | E21: 81301500253 | F21: =_xlfn.XLOOKUP(D21,Sheet1!C:C,Sheet1!E:E,0) -> 18igEpbLm_ONenrCMJadgAzpFPZbGhoUe
A22: E2 | B22: Interlink | C22: 2-Leg | D22: E2-G2L-C-ITEL-Slab.pdf | E22: New request-17 | F22: =_xlfn.XLOOKUP(D22,Sheet1!C:C,Sheet1!E:E,0) -> 1jAeuS5W1OL07JMYI6w25ehOqjlWCk226
A23: E2 | B23: A-Plus | C23: 2-Layer (6+2) | D23: E2-T2-Aplus-1.pdf | E23: New request-18 | F23: =_xlfn.XLOOKUP(D23,Sheet1!C:C,Sheet1!E:E,0) -> 1Tku1Syx86WBxUmLAVBPV1xPWbWQG8rsv
A24: E2 | B24: A-Plus | C24: 2-Layer (6+2) | D24: E2-T2-Aplus-2.pdf | E24: New request-19 | F24: =_xlfn.XLOOKUP(D24,Sheet1!C:C,Sheet1!E:E,0) -> 0
A25: N1 | B25: TCC | C25: 1-Leg | D25: N1-G1L-Soil.pdf | E25: 81301500176 | F25: =_xlfn.XLOOKUP(D25,Sheet1!C:C,Sheet1!E:E,0) -> 1-IeVCm7MaL17VBfeMXbmz-jABWUCj8qu
A26: N1 | B26: TCC | C26: 1-Leg | D26: N1-G1L-Slab.pdf | E26: 81301500232 | F26: =_xlfn.XLOOKUP(D26,Sheet1!C:C,Sheet1!E:E,0) -> 1hm_iIRFcO_CmXTF15AmwqXIwVAkQE4n2
A27: N1 | B27: TCC | C27: 1-Layer (L-Leg) | D27: N1-T1-L.pdf | E27: 81301500188 | F27: =_xlfn.XLOOKUP(D27,Sheet1!C:C,Sheet1!E:E,0) -> 1pP2-MjeVOrGTnnRyQwaa49kvZqkAd9Ym
A28: N1 | B28: TCC | C28: 1-Layer (Pipe-Leg) | D28: N1-T1-P.pdf | E28: 81301500192 | F28: =_xlfn.XLOOKUP(D28,Sheet1!C:C,Sheet1!E:E,0) -> 1TrCr793kbOCo5707Pxb0TYkYrBuWIGo3
A29: N2 | B29: TCC | C29: 1-Leg | D29: N2-G1L-Soil.pdf | E29: 81301500230 | F29: =_xlfn.XLOOKUP(D29,Sheet1!C:C,Sheet1!E:E,0) -> 1ICZpRmz1GqD-c6fmdk_co7a9KyhWU14J
A30: N2 | B30: TCC | C30: 1-Layer (L-Leg) | D30: N2-T1-L.pdf | E30: 81301500199 | F30: =_xlfn.XLOOKUP(D30,Sheet1!C:C,Sheet1!E:E,0) -> 1JGmR7t3sswrHFnt4SrQ422zPR7LPfMJa
A31: N2 | B31: TCC | C31: 1-Layer (Pipe-Leg) | D31: N2-T1-P.pdf | E31: 81301500190 | F31: =_xlfn.XLOOKUP(D31,Sheet1!C:C,Sheet1!E:E,0) -> 1KCFLQphtGjUX8GKXdkbn8XZvSWYm-DXv
A32: N2 | B32: TCC | C32: Container | D32: N2-CR-Corner Box.pdf | E32: 81301500235 | F32: =_xlfn.XLOOKUP(D32,Sheet1!C:C,Sheet1!E:E,0) -> 19p4ljUq-N0pc4ZfrZXFdiW257gu5hm7m
A33: N2 | B33: TCC | C33: Container | D33: N2-CR-Transfer Beam.pdf | E33: 81301500225 | F33: =_xlfn.XLOOKUP(D33,Sheet1!C:C,Sheet1!E:E,0) -> 1ZUXB96PY2hQLi5ZYqUJ2FnJqQNNqI6Fb
A34: N3 | B34: TCC | C34: 1-Leg | D34: N3-G1L-Soil.pdf | E34: 81301500178 | F34: =_xlfn.XLOOKUP(D34,Sheet1!C:C,Sheet1!E:E,0) -> 1tTwkdj3qDclHwIvRp1XC5KZkRQCracI_
A35: N3 | B35: TCC | C35: 2-Leg | D35: N3-G2L-Soil.pdf | E35: 81301500215 | F35: =_xlfn.XLOOKUP(D35,Sheet1!C:C,Sheet1!E:E,0) -> 1ibM_LgVADpHWjnzmO7fzMPoARNBZ7BJS
A36: N3 | B36: TCC | C36: 1-Layer (L-Leg) | D36: N3-T1-L.pdf | E36: 81301500177 | F36: =_xlfn.XLOOKUP(D36,Sheet1!C:C,Sheet1!E:E,0) -> 1HmjIT1rcuDkYsRYeMqx51qCKnFsJOKe-
... A65: E1 | B65: Interlink | C65: 1-Leg | D65: E1-G1L-C-ITEL-Slab.pdf | E65: 81301500164 | F65: =_xlfn.XLOOKUP(D65,Sheet1!C:C,Sheet1!E:E,0) -> 1Hj6pWsxGwsxqfWiYylNT3PmTl0aQxAu2
A66: E1 | B66: Interlink | C66: 1-Leg | D66: E1-G1L-C-ITEL-Soil.pdf | E66: New request-1 | F66: =_xlfn.XLOOKUP(D66,Sheet1!C:C,Sheet1!E:E,0) -> 1xXgFAPkNMxnCaOTLT__xt1neCiSgbsKd
A67: E2 | B67: Huawei 2020 | C67: 2-Leg | D67: E2-G2L-HW-H3.0-Slab.pdf | E67: New request-16 | F67: =_xlfn.XLOOKUP(D67,Sheet1!C:C,Sheet1!E:E,0) -> 13WGzWcME9yEWNRgXBRcux33g3BNq4_Vv
A68: E2 | B68: Huawei 2020 | C68: 2-Leg | D68: E2-G2L-HW-H3.0-Soil.pdf | E68: 81301500242 | F68: =_xlfn.XLOOKUP(D68,Sheet1!C:C,Sheet1!E:E,0) -> 1AK-Fqgfcm7fHfAk1ikZ2ZpBhO9eG-rSD
...

Sheet Sheet1
B2: Structure Name | C2: File Name | D2: Structure Code | E2: File ID
B3: E1-G4L-Petchtanjai | C3: E1-G4L-Petchtanjai.pdf | D3: 123456789 | E3: 1E3iM_fQdEkK-F5j8NdfkVghGY0hr7pCQ | F3: =_xlfn.XLOOKUP(C3,'Drawing List Database'!D:D,'Drawing List Database'!B:B,0) -> Petchtanjai
B4: E1-G1L-C-Hatari-2-Soil | C4: E1-G1L-C-Hatari-2-Soil.pdf | D4: 081301500258 | E4: 1kBKgOelz0qlK5AEENq8V6xkgVn17rgte | F4: =_xlfn.XLOOKUP(C4,'Drawing List Database'!D:D,'Drawing List Database'!B:B,0) -> Hatari
B5: E2-G2L-C-Aplus-Slab | C5: E2-G2L-C-Aplus-Slab.pdf | D5: 081301500261 | E5: 1ULlDfXUrJykZV3D-Hcj0CExSMgAW1FoH | F5: =_xlfn.XLOOKUP(C5,'Drawing List Database'!D:D,'Drawing List Database'!B:B,0) -> A-Plus
B6: E2-T2-Aplus-1 | C6: E2-T2-Aplus-1.pdf | D6: New request-18 | E6: 1Tku1Syx86WBxUmLAVBPV1xPWbWQG8rsv | F6: =_xlfn.XLOOKUP(C6,'Drawing List Database'!D:D,'Drawing List Database'!B:B,0) -> A-Plus
B7: E1-G1L-MRV-3PV-4PV_Soil | C7: E1-G1L-MRV-3PV-4PV_Soil.pdf | D7: 81301500165 | E7: 136Dmht6m_OF3coDAYRVAB1xBq9ZWqRiO | F7: =_xlfn.XLOOKUP(C7,'Drawing List Database'!D:D,'Drawing List Database'!B:B,0) -> Interlink
B8: E1-G1L-MRV-3PV-4PV_Slab | C8: E1-G1L-MRV-3PV-4PV_Slab.pdf | D8: New request-7 | E8: 1c4h-9rUZDxBdG4tCUTKrZx0VOzHVcA5g | F8: =_xlfn.XLOOKUP(C8,'Drawing List Database'!D:D,'Drawing List Database'!B:B,0) -> M.R.V
B9: E1-G1L-C-Transpower-V-Soil | C9: E1-G1L-C-Transpower-V-Soil.pdf | D9: New request-5 | E9: 172DCyPSuXJYpT4Ws7FigO5ENDNIrmTPG | F9: =_xlfn.XLOOKUP(C9,'Drawing List Database'!D:D,'Drawing List Database'!B:B,0) -> Transpower
B10: E1-G1L-C-Transpower-V-Slab | C10: E1-G1L-C-Transpower-V-Slab.pdf | D10: New request-4 | E10: 100nbKdr6FIAClLOncY0C0aIM0h0AG2d9 | F10: =_xlfn.XLOOKUP(C10,'Drawing List Database'!D:D,'Drawing List Database'!B:B,0) -> Transpower
B11: E1-G1L-C-Transpower-H-Soil | C11: E1-G1L-C-Transpower-H-Soil.pdf | D11: New request-3 | E11: 11K1f04ZLijvHhHieef3OME7LgRV2a-rB | F11: =_xlfn.XLOOKUP(C11,'Drawing List Database'!D:D,'Drawing List Database'!B:B,0) -> Transpower
B12: E1-G1L-C-Transpower-H-Slab | C12: E1-G1L-C-Transpower-H-Slab.pdf | D12: New request-2 | E12: 10In5XjyZlfD15fBecD3lrLwj9hkpWNXn | F12: =_xlfn.XLOOKUP(C12,'Drawing List Database'!D:D,'Drawing List Database'!B:B,0) -> Transpower
B13: E1-T1-MRV-3PV-4PV | C13: E1-T1-MRV-3PV-4PV.pdf | D13: New request-11 | E13: 1D0fPzrHWduR11PsbIv2Bw0xtQNsKDbNH | F13: =_xlfn.XLOOKUP(C13,'Drawing List Database'!D:D,'Drawing List Database'!B:B,0) -> M.R.V
B14: E2-G2L-C-Qualia-Soil | C14: E2-G2L-C-Qualia-Soil.pdf | D14: 081301500253 | E14: 18igEpbLm_ONenrCMJadgAzpFPZbGhoUe | F14: =_xlfn.XLOOKUP(C14,'Drawing List Database'!D:D,'Drawing List Database'!B:B,0) -> Qualia
B15: E1-G2L-C-Qualia | C15: E1-G2L-C-Qualia.pdf | D15: 081301500167 | E15: 1mXHFwhsW8N4APfwTeo899MHBAw8xNHSR | F15: =_xlfn.XLOOKUP(C15,'Drawing List Database'!D:D,'Drawing List Database'!B:B,0) -> Qualia
B16: N1-G1L-Soil | C16: N1-G1L-Soil.pdf | D16: 081301500176 | E16: 1-IeVCm7MaL17VBfeMXbmz-jABWUCj8qu | F16: =_xlfn.XLOOKUP(C16,'Drawing List Database'!D:D,'Drawing List Database'!B:B,0) -> TCC
B17: E1-T1-L-MRV-1 | C17: E1-T1-L-MRV-1.pdf | D17: 81301500245 | E17: 1bi3vbRiTYhBtAcBnaH8JcyBMQvHLftq- | F17: =_xlfn.XLOOKUP(C17,'Drawing List Database'!D:D,'Drawing List Database'!B:B,0) -> M.R.V
B18: E1-G1L-HW | C18: E1-G1L-HW.pdf | D18: 81301500168 | E18: 1yNq4z9_Zf-EVsKqtNbuQ5v4W9xOfnsT3 | F18: =_xlfn.XLOOKUP(C18,'Drawing List Database'!D:D,'Drawing List Database'!B:B,0) -> Huawei 2020
B19: R4L-H-4PV | C19: R4L-H-4PV.pdf | D19: 081301500248 | E19: 1JN2mg2hgea-FZrA8nqb6BeaVpHqD2AyV | F19: =_xlfn.XLOOKUP(C19,'Drawing List Database'!D:D,'Drawing List Database'!B:B,0) -> TCC
B20: R2-R4L-H | C20: R2-R4L-H.pdf | D20: 081301500247 | E20: 1ngdzMz6BcW1MMXfynPFkyChxdYwAHDiY | F20: =_xlfn.XLOOKUP(C20,'Drawing List Database'!D:D,'Drawing List Database'!B:B,0) -> TCC
B21: E1-G2L-C-Aplus-Soil | C21: E1-G2L-C-Aplus-Soil.pdf | D21: 081301500171 | E21: 1LQSZp8WBfiz8GKZHyjP7E1BWAclDvbr1 | F21: =_xlfn.XLOOKUP(C21,'Drawing List Database'!D:D,'Drawing List Database'!B:B,0) -> A-Plus
B22: E1-T1-APlus | C22: E1-T1-APlus.pdf | D22: 081301500239 | E22: 13drwIPa8sG3i1ILXjSrA0O_EVP67SN0l | F22: =_xlfn.XLOOKUP(C22,'Drawing List Database'!D:D,'Drawing List Database'!B:B,0) -> A-Plus
B23: E1-G4L-H3.5-Hatari | C23: E1-G4L-H3.5-Hatari.pdf | D23: 81301500172 | E23: 1hXgsTqbUAUOYyo5Yk8-wW8Vebtc8XVQg | F23: =_xlfn.XLOOKUP(C23,'Drawing List Database'!D:D,'Drawing List Database'!B:B,0) -> Hatari/AAL
B24: E1-G4L-H2.5-Hatari | C24: E1-G4L-H2.5-Hatari.pdf | D24: 81301500170 | E24: 1uZ_nTiNFX39rNKRVxPdqRqJT_SIIK_9q | F24: =_xlfn.XLOOKUP(C24,'Drawing List Database'!D:D,'Drawing List Database'!B:B,0) -> Hatari/AAL
B25: R1-R4L-H | C25: R1-R4L-H.pdf | D25: 081301500240 | E25: 104ST2J54j7kbRuXOG_8zTRnz40P3F9jA | F25: =_xlfn.XLOOKUP(C25,'Drawing List Database'!D:D,'Drawing List Database'!B:B,0) -> TCC
B26: E1-G1L-C-Aplus-Soil | C26: E1-G1L-C-Aplus-Soil.pdf | D26: 081301500255 | E26: 11bpfI4rfF9_ccIsYiRFVHfkL4wvcZUPf | F26: =_xlfn.XLOOKUP(C26,'Drawing List Database'!D:D,'Drawing List Database'!B:B,0) -> A-Plus
B27: E1-T1-L-MRV-2 | C27: E1-T1-L-MRV-2.pdf | D27: 81301500250 | E27: 16IEbenyjp10vcTqVir_xX3UnIC_lQQkq | F27: =_xlfn.XLOOKUP(C27,'Drawing List Database'!D:D,'Drawing List Database'!B:B,0) -> M.R.V
B28: N4-G2L-Slab | C28: N4-G2L-Slab.pdf | D28: 081301500254 | E28: 1dXmQvqHc7Bejnl3JNBMf0ez8bQsa2kbL | F28: =_xlfn.XLOOKUP(C28,'Drawing List Database'!D:D,'Drawing List Database'!B:B,0) -> TCC
B29: N3-T2-P | C29: N3-T2-P.pdf | D29: 081301500231 | E29: 1H_DunUA-m0ENGxK8WLnlRNEjZNLz3u9- | F29: =_xlfn.XLOOKUP(C29,'Drawing List Database'!D:D,'Drawing List Database'!B:B,0) -> TCC
B30: N3-T2-L | C30: N3-T2-L.pdf | D30: 081301500236 | E30: 1fgjfoJghOl51nQacxox1dTYdpNo_Typh | F30: =_xlfn.XLOOKUP(C30,'Drawing List Database'!D:D,'Drawing List Database'!B:B,0) -> TCC
B31: N1-T1-L | C31: N1-T1-L.pdf | D31: 081301500188 | E31: 1pP2-MjeVOrGTnnRyQwaa49kvZqkAd9Ym | F31: =_xlfn.XLOOKUP(C31,'Drawing List Database'!D:D,'Drawing List Database'!B:B,0) -> TCC
B32: N1-G1L-Slab | C32: N1-G1L-Slab.pdf | D32: 081301500232 | E32: 1hm_iIRFcO_CmXTF15AmwqXIwVAkQE4n2 | F32: =_xlfn.XLOOKUP(C32,'Drawing List Database'!D:D,'Drawing List Database'!B:B,0) -> TCC
B33: E1-T2-Aplus | C33: E1-T2-Aplus.pdf | D33: 81301500244 | E33: 1tAi1YK8aU1n1DABUVJK1cOugzhNYQdf9 | F33: =_xlfn.XLOOKUP(C33,'Drawing List Database'!D:D,'Drawing List Database'!B:B,0) -> A-Plus
B34: E1-G2L-HW | C34: E1-G2L-HW.pdf | D34: 081301500166 | E34: 18XWF2f2vyKhemprwF-_oVq6AqoFMxsri | F34: =_xlfn.XLOOKUP(C34,'Drawing List Database'!D:D,'Drawing List Database'!B:B,0) -> Huawei 2020
B35: E1-G1L-C-Aplus-Slab | C35: E1-G1L-C-Aplus-Slab.pdf | D35: 081301500173 | E35: 1geEYmQI6fINaxQkXCKeWmB_3CZB2m8bW | F35: =_xlfn.XLOOKUP(C35,'Drawing List Database'!D:D,'Drawing List Database'!B:B,0) -> A-Plus
B36: E1-G1L-C-Hatari-2-Slab | C36: E1-G1L-C-Hatari-2-Slab.pdf | D36: 81301500257 | E36: 1r8JLhcKS6rCZbfiUy66nXE8VJA6kX_F9 | F36: =_xlfn.XLOOKUP(C36,'Drawing List Database'!D:D,'Drawing List Database'!B:B,0) -> Hatari
B37: N3-G1L-Slab | C37: N3-G1L-Slab.pdf | D37: 081301500263 | E37: 1TN8Y18S6wEhaX-oYxe4OcE9qDZiuuNvM | F37: =_xlfn.XLOOKUP(C37,'Drawing List Database'!D:D,'Drawing List Database'!B:B,0) -> TCC
B38: N2-G1L-Slab | C38: N2-G1L-Slab.pdf | D38: 081301500241 | E38: 19sach7Bnb3Chij2_rrX5kC6n-Vbo8fNx | F38: =_xlfn.XLOOKUP(C38,'Drawing List Database'!D:D,'Drawing List Database'!B:B,0) -> TCC
B39: E2-G2L-C-Aplus-Soil | C39: E2-G2L-C-Aplus-Soil.pdf | D39: 081301500265 | E39: 1YtoEUUvgCLiQnIhOiMyvVcGWnrW9Saub | F39: =_xlfn.XLOOKUP(C39,'Drawing List Database'!D:D,'Drawing List Database'!B:B,0) -> A-Plus
B40: E1-G2L-C-Aplus-Slab | C40: E1-G2L-C-Aplus-Slab.pdf | D40: 081301500266 | E40: 17X41Eeu8QM69lPLvgcYIGt4LEhBRjfh8 | F40: =_xlfn.XLOOKUP(C40,'Drawing List Database'!D:D,'Drawing List Database'!B:B,0) -> A-Plus
B41: E1-G1L-MRV-3PV-2PV | C41: E1-G1L-MRV-3PV-2PV.pdf | D41: New request-6 | E41: 1sg8m3KNgKqCz4Co1FKO82cwDcfJ7foWF | F41: =_xlfn.XLOOKUP(C41,'Drawing List Database'!D:D,'Drawing List Database'!B:B,0) -> M.R.V
...
